Workbook

Sheet Sheet1
A1: in | B1: TIME | C1: DATE | D1: NAME | E1: DESCRIPTION | F1: IMEI | G1: PHONE NUMBER | H1: PRICE | I1: Amount paid | J1: STATUS | K1: IMEI FOR SWAPPED DEAL | L1: RECORD_ID | M1: DEAL LOCATION | N1: INTERNAL NOTE | O1: PAID DATE | P1: EXPENSE AMOUNT | Q1: EXPENSE DESCRIPTION | R1: CALCULATED PROFIT
A2: 1 | B2: 1 | C2: 46070 | D2: DEMEX | E2: IPHONE 16 BLACK UPDATE | G2: 2347067462101 | H2: 2500 | I2: 2500 | J2: paid | L2: 9dcfec929c764ae7a52bfd4caf78d6c5
A3: 2 | B3: 2 | C3: 46070 | D3: DAH UNIQUE | E3: GOLD IPHONE 14 PRO | G3: 2349070536253 | H3: 2500 | I3: 2500 | J3: PAID | L3: e1e76866b2b44537a367a48baed4cbb7
A4: 3 | B4: 3 | C4: 46070 | D4: HUNTER LIFE | E4: SWAPPED IPHONE 13 TO 11 PRO SILVER | G4: =IF(LEN(TRIM(D4))=0,"",IFNA(VLOOKUP(UPPER(TRIM(D4)),'CLIENT DIRECTORY'!A:B,2,FALSE),"")) | H4: 185000 | I4: 185000 | J4: PAID | L4: 252820e05f6641b4aec1103a18424f72
A5: 4 | B5: 4 | C5: 46070 | D5: RICKY | E5: IPHONE 16 PRO GOLD 100% SWAPPED WITH IPHONE 15 PRO 512GB | G5: =IF(LEN(TRIM(D5))=0,"",IFNA(VLOOKUP(UPPER(TRIM(D5)),'CLIENT DIRECTORY'!A:B,2,FALSE),"")) | H5: 280000 | I5: 280000 | J5: PAID | L5: 13b8f92dda7b4ff7825daa1e2676f734
A6: 5 | B6: 5 | C6: 46070 | D6: OSES | E6: IPHONE 14 PLUS UPDATE MIDNIGHT COLOR | G6: =IF(LEN(TRIM(D6))=0,"",IFNA(VLOOKUP(UPPER(TRIM(D6)),'CLIENT DIRECTORY'!A:B,2,FALSE),"")) | H6: 2500 | I6: 2500 | J6: PAID | L6: c2a8339184ce430f975db6123c51a7fb
A7: 6 | B7: 6 | C7: 46070 | D7: KEMI FROM SEUN | E7: IPHONE 15 PRO MAX 512GB TO IPHONE | G7: =IF(LEN(TRIM(D7))=0,"",IFNA(VLOOKUP(UPPER(TRIM(D7)),'CLIENT DIRECTORY'!A:B,2,FALSE),"")) | H7: 1500000 | I7: 1500000 | J7: PAID | L7: 3debc2aabaa842ce9d440b9b84980f2d
A8: 7 | B8: 7 | C8: 46070 | D8: IBIRONKE FAVOUR | E8: APPLE ID CREATE & SIGN IN | G8: =IF(LEN(TRIM(D8))=0,"",IFNA(VLOOKUP(UPPER(TRIM(D8)),'CLIENT DIRECTORY'!A:B,2,FALSE),"")) | H8: 10000 | I8: 10000 | J8: PAID | L8: ad63bb932f7e47abb64bae4d1546a4d8
A9: 8 | B9: 8 | C9: 46070 | D9: CLINTON GADGET | E9: IPHONE 16 256GB 354178509660284 | G9: =IF(LEN(TRIM(D9))=0,"",IFNA(VLOOKUP(UPPER(TRIM(D9)),'CLIENT DIRECTORY'!A:B,2,FALSE),"")) | H9: 800000 | I9: 800000 | J9: PAID | L9: ff964ae5a2f2444187915c0d21934773
A10: 9 | B10: 9 | C10: 46070 | D10: NURUDEEN | E10: CHIP FOR IPHONE 12 PRO PACIFIC BLUE | G10: 09122727950 | H10: 25000 | I10: 25000 | J10: PAID | L10: fb2d541894b74a0a9fcffa10378d8580
A11: 10 | B11: 10 | C11: 46070 | D11: WIZZY | E11: NATURAL TITANIUM IPHONE 15 PRO MAX IOS UPDATE | G11: 2348108686713 | H11: 2500 | I11: 2500 | J11: PAID | L11: 38425b848c1e4f8195ec6df4938be5ca
A12: 11 | B12: 11 | C12: 46068 | D12: ZEE TECH | E12: IPHONE 13 IOS UPDATE | G12: 2349033724061 | H12: 2500 | I12: 2500 | J12: PAID | L12: 7f9250f3a89542a69db22bdb2807f36b
A13: 12 | B13: 12 | C13: 46069 | D13: ZEE TECH | E13: IPHONE 13 PRO MAX IOS UPDATE | G13: 2349033724061 | H13: 2500 | I13: 2500 | J13: PAID | L13: c8dc8dfa28c343c484a7f2ba7fbf5b3f
A14: 13 | B14: 13 | C14: 46070 | D14: TUNDE BABZ | E14: CHIP FIX | G14: 2348130793960 | H14: 10000 | I14: 10000 | J14: PAID | L14: 8d69b845461f43ccad08fac46ac2348c
A15: 14 | B15: 14 | C15: 46070 | D15: KAYWISE | E15: IPHONE 15 PRO MAX P + E 512GB | G15: 2349032614464 | H15: 1000000 | I15: 1000000 | J15: PAID | L15: 81a4d573dc4a4afeab545d034c19ae52
A16: 15 | B16: 15 | C16: 46070 | D16: IAMFODIL | E16: CHIP FIX | G16: =IF(LEN(TRIM(D16))=0,"",IFNA(VLOOKUP(UPPER(TRIM(D16)),'CLIENT DIRECTORY'!A:B,2,FALSE),"")) | H16: 10000 | I16: 10000 | J16: PAID | L16: 1957f2a4eeea493ea424761b0b10eb60
A17: 16 | C17: 46070 | D17: DON | E17: IMESSAGE FIX | G17: 2348137676322 | H17: 5000 | J17: PAID | L17: 61b620789dbe4227a38d21fd9329b837
A18: 17 | B18: 1 | C18: 46064 | D18: TECH JAR | E18: GREEN IPHONE 11 FLASH | G18: 2347047512596 | H18: 3000 | I18: 3000 | J18: PAID | L18: 65b3dd616fef46bab83f7647525708c3
A19: 18 | B19: 2 | C19: 46065 | D19: DAPPER | E19: BLACK IPHONE 15 UPDATE | G19: 2349166394378 | H19: 3000 | I19: 3000 | J19: paid | L19: 3ec23fa2218f4c98b42e52e295adcada
A20: 19 | B20: 3 | C20: 46066 | D20: DEMEX | E20: IPHONE 12 PRO UPDATE | G20: 2347067462101 | H20: 2000 | I20: 2000 | J20: paid | L20: 4676473684ca4ecd9d5345b5515d9aa0
A21: 20 | B21: 4 | C21: 46063 | D21: NUMBER TELLOS | E21: NEW JERSEY USA NUMBER AND ULTRAMOBILE NUMBER REFILL | G21: 2348066173750 | H21: 90000 | J21: PAID | K21: PAID 90K OUT OF 180K | L21: 6d92fa4e661549589e511ea2c1109f42
A22: 21 | B22: 5 | C22: 46063 | D22: DAMBOX | E22: GOLD IPHONE 11 PRO MAX IOS UPDATE | G22: 09040943517 | H22: 2500 | J22: PAID | L22: 08b7c305cd444e0fb756a6a1b4fed2c7
A23: 22 | B23: 6 | C23: 46071 | D23: CH4 | E23: OUTSTANDING | G23: 2348131941406 | H23: 12500 | J23: PAID | L23: f396e68ad7e844268c3cd2c338cb4ec9
A24: 23 | B24: 7 | C24: 46060 | D24: VERTEX | E24: PINK IPHONE 15 PLUS UPDATE | G24: 2348103663581 | H24: 2500 | J24: PAID | L24: 4590d23eb8fa43579501fbc6bd071bd1
A25: 24 | B25: 8 | C25: 46060 | D25: MIKKY | E25: IPHONE 13 PRO MAX CHIP | G25: =IF(LEN(TRIM(D25))=0,"",IFNA(VLOOKUP(UPPER(TRIM(D25)),'CLIENT DIRECTORY'!A:B,2,FALSE),"")) | H25: 20000 | J25: RETURNED | L25: 9bbbf52992df41bca266eeb13d53ad91
A26: 25 | B26: 9 | C26: 46060 | D26: PRINZE GADGET | E26: IPHONE 13 UPDATE | G26: =IF(LEN(TRIM(D26))=0,"",IFNA(VLOOKUP(UPPER(TRIM(D26)),'CLIENT DIRECTORY'!A:B,2,FALSE),"")) | H26: 2500 | J26: PAID | L26: f902b4c8ea8c49a2bdb4466ed2b99884
A27: 26 | B27: 10 | C27: 46058 | D27: DENIS4WARD | E27: PS4 SLIM AND ONE GAMEPAD | G27: 2348038551439 | H27: 225000 | J27: PAID | L27: c6f548765acd4277a3081301ea7558e0
A28: 27 | B28: 11 | C28: 46057 | D28: MIDE GADGET | E28: BLUE IPHONE 16 UPDATE | G28: =IF(LEN(TRIM(D28))=0,"",IFNA(VLOOKUP(UPPER(TRIM(D28)),'CLIENT DIRECTORY'!A:B,2,FALSE),"")) | H28: 2500 | J28: PAID | L28: 1a175228683e4c7f83fa4ff7d78edd6c
A29: 28 | B29: 12 | C29: 46056 | D29: ZADDY ROLLAND | E29: TEAL 16 P+E BALANCE | G29: 2348050554029 | H29: 450000 | J29: PENDING | L29: cfb45f1f05604357b7eca2af401cc1b6
A30: 29 | B30: 13 | C30: 46056 | D30: ZADDY ROLLAND | E30: TEAL 16 P+E UPDATE | G30: 2348050554029 | H30: 2500 | J30: UNPAID | L30: 08f797e6e883406aafbd18de33d0fe07
A31: 30 | B31: 14 | C31: 46071 | D31: JAMEX | E31: OUTSTANDING BALANCE | G31: 2347033260364 | H31: 395000 | J31: PENDING | L31: 19d21d47029d41d0af0fc380928ba2cb
A32: 31 | B32: 15 | C32: 46050 | D32: AYANFE | E32: APPLE ID RECOVERY | G32: 2348138108648 | H32: 10000 | J32: PAID | L32: ee70de5352b248dda16ed018caac6dab
A33: 32 | B33: 16 | C33: 46049 | D33: DENIS4WARD | E33: ILESHA DRIVER | G33: 2348038551439 | H33: 5000 | J33: PAID | L33: 1e7c1962321a484b82cda53c4bbc338e
B34: 17 | C34: 46049 | D34: PRINZE GADGETS | E34: MIDNIGET LOCKED 14 PLUS. 81% | F34: 356295374969208 | G34: 2348073229131 | H34: 280000 | J34: PAID | L34: 523b7a62015f4f16aaa6fdcfe135e889
A35: 33 | B35: 18 | C35: 46049 | D35: DENIS4WARD | E35: GAS FILL | G35: 2348038551439 | H35: 16250 | J35: PAID | L35: 69bdbb71ddb34659b3c51ffc3f27914b
A36: 34 | B36: .. | C36: .. | D36: .. | E36: .. | F36: .. | G36: =IF(LEN(TRIM(D36))=0,"",IFNA(VLOOKUP(UPPER(TRIM(D36)),'CLIENT DIRECTORY'!A:B,2,FALSE),"")) | H36: .. | L36: 259c651fb2fc45bea1649447a37d344c
A37: 35 | B37: 1 | C37: 46071 | D37: NURUDEEN | E37: NATURAL TITANIUM 15 PRO UPDATE | G37: 09122727950 | H37: 2500 | J37: PAID | L37: 3a3ee298459f443e97ad50509eb0e3dd
A38: 36 | B38: 2 | C38: 46071 | D38: DAMBOX | E38: ORANGE IPHONE 17 PRO IOS UPDATE | G38: 09040943517 | H38: 2500 | J38: PAID | L38: 860f6063e1f64ed69181fea34c1331b6
A39: 37 | B39: 3 | C39: 46071 | D39: KAYWISE | E39: ULTRAMARINE IPHONE 16 PLUS UPDATE | G39: 2349032614464 | H39: 2000 | I39: 2000 | J39: PAID | L39: b263752956ea49d493083d288125523d
A40: 38 | B40: 4 | C40: 46071 | D40: PANKEY | E40: WHITE IPHONE 15 FIX BATTERY FLASH | G40: =IF(LEN(TRIM(D40))=0,"",IFNA(VLOOKUP(UPPER(TRIM(D40)),'CLIENT DIRECTORY'!A:B,2,FALSE),"")) | H40: 2500 | J40: PAID | L40: 1cbe6952e28545e786673dbdbb797adf
...

Sheet Debtors Summary
A1: Name | B1: Outstanding Amount
A2: BIGMO | B2: NGN 1,150,000
A3: MBENZ | B3: NGN 875,000
A4: DAMBOX | B4: NGN 825,000
A5: AFRIKA | B5: NGN 580,000
A6: MD GADGS | B6: NGN 475,000
A7: ZADDY ROLLAND | B7: NGN 452,500
A8: JAMEX | B8: NGN 395,000
A9: SAMMY CONCEPT | B9: NGN 392,500
A10: PHLEMZY | B10: NGN 305,000
A11: DREY | B11: NGN 300,000
A12: ZEE | B12: NGN 37,500
... A52: ISAIAH BIKEMAN | B52: NGN 2,000

Sheet CLIENT DIRECTORY
A1: NAME | B1: PHONE NUMBER
A2: ACTIVE | B2: 2348145310779
A3: ADEBAYO ROKEEB | B3: 2348073670589
A4: ADESOLA AYODELE | B4: 2349166314423
A5: ADEX GADGETS | B5: 2347067852062
A6: ADEYEYE | B6: 2347069117214
A7: AFRIKA | B7: 2349032711183
A8: AHB | B8: 2349136777731
A9: AKINPELUMI MEE | B9: 2349039596257
A10: ANNIE | B10: 2348141375361
A11: ANOINTED WEALTH | B11: 2348137226383
A12: AREMO | B12: 2349037888923
... A176: ZINTO | B176: 2349068103734

Sheet CASH FLOW
A1: DATE | B1: CATEGORY | C1: AMOUNT | D1: DESCRIPTION | E1: CREATED BY | F1: SOURCE | G1: PAYMENT_STATUS | H1: TYPE | I1: COST_PRICE | J1: PAYMENT_DATE | K1: Column 11 | L1: Column 12 | M1: Column 13 | N1: Column 14 | O1: Column 15 | P1: Column 16 | Q1: Column 17 | R1: Column 18 | S1: Column 19 | T1: Column 20 | U1: Column 21 | V1: Column 22 | W1: Column 23 | X1: Column 24 | Y1: Column 25 | Z1: Column 26 | AA1: Column 27 | AB1: Column 28 | AC1: Column 29 | AD1: Column 30 | AE1: Column 31 | AF1: Column 32 | AG1: Column 33 | AH1: Column 34 | AI1: Column 35
A2: 46146 | B2: SERVICE PROFIT | C2: 5000 | D2: ICLOUD OPENING: NIGERIA | NOTE: Blessing oluwaseun, blessingoluwaseunogunleye@gmail.com, 07035919593 , Password provided: AppleID2026# adjusted date to 2004 from 2006 | E2: SAM EXCHANGE | F2: income | G2: PAID | H2: service | J2: 46146
A3: 46146 | B3: SERVICE PROFIT | C3: 2500 | D3: IPHONE 12 PRO MAX GOLD IOS UPDATE | E3: GLORY HOLLAH GADGETS | F3: income | G3: PAID | H3: service | J3: 46146
A4: 46146 | B4: SERVICE PROFIT | C4: 3000 | D4: IPHONE 14 PRO IOS UPDATE: SPACE BLACK | E4: DELIGHT | F4: income | G4: PAID | H4: service | J4: 46146
A5: 46146 | B5: SERVICE PROFIT | C5: 2500 | D5: IPHONE 15 PLUS IOS UPDATE: sky blue | E5: WIZZY | F5: income | G5: PAID | H5: service | J5: 46146
A6: 46146 | B6: SERVICE PROFIT | C6: 5000 | D6: IPHONE XSMAX SYSTEM DATA SPACE FIX | E6: IJEOMA | F6: income | G6: PAID | H6: service | J6: 46146
A7: 46146 | B7: SERVICE PROFIT | C7: 25000 | D7: STABLE CHIP FOR IPHONE 12 | E7: DAMOLA FCG | F7: income | G7: PAID | H7: service | J7: 46146
A8: 46147 | B8: PHONE PROFIT | C8: 80000 | D8: IPHONE 17 PRO MAX | E8: ANOINTED WEALTH | F8: income | G8: PAID | H8: phone | I8: 1180000 | J8: 46147
A9: 46147 | B9: SERVICE PROFIT | C9: 3000 | D9: CHIP FIX | E9: EMMANUEL OLAMILEKAN | F9: income | G9: PAID | H9: service | J9: 46147
A10: 46147 | B10: SERVICE PROFIT | C10: 2000 | D10: CUSTOMER FILE TRANSFER | E10: ANOINTED WEALTH | F10: income | G10: PAID | H10: service | J10: 46147
A11: 46147 | B11: SERVICE PROFIT | C11: 3000 | D11: ICLOUD OPENING: NIGERIA | E11: AHB | F11: income | G11: PAID | H11: service | J11: 46147
A12: 46147 | B12: SERVICE PROFIT | C12: 10000 | D12: ICLOUD OPENING: USA | E12: OLUFAD TELECOMMUNICATION | F12: income | G12: PAID | H12: service | J12: 46147
A13: 46147 | B13: SERVICE PROFIT | C13: 2500 | D13: IPHONE 12 IOS UPDATE: Blue | E13: BIG INVESTOR | F13: income | G13: PAID | H13: service | J13: 46147
A14: 46147 | B14: SERVICE PROFIT | C14: 3000 | D14: IPHONE 17 PRO MAX IOS UPDATE: silver | E14: ADEX GADGETS | F14: income | G14: PAID | H14: service | J14: 46147
A15: 46147 | B15: SERVICE PROFIT | C15: 5000 | D15: LOCATION SPOOFING | E15: TIMILEYIN | F15: income | G15: PAID | H15: service | J15: 46147
A16: 46147 | B16: SERVICE PROFIT | C16: 2500 | D16: iPhone 11 Red 64GB IOS UPDATE | E16: SMART | F16: income | G16: PAID | H16: service | J16: 46147
A17: 46148 | B17: SERVICE PROFIT | C17: 75000 | D17: 3 MONTHS ESIM | E17: TUNA MONEY | F17: income | G17: PAID | H17: service | J17: 46148
A18: 46148 | B18: SERVICE PROFIT | C18: 5000 | D18: ICLOUD FIXING | E18: FOLAKEMI | F18: income | G18: PAID | H18: service | J18: 46148
A19: 46148 | B19: SERVICE PROFIT | C19: 3000 | D19: ICLOUD SIGN IN FIX | E19: PRINCE MOSES | F19: income | G19: PAID | H19: service | J19: 46148
A20: 46148 | B20: SERVICE PROFIT | C20: 3000 | D20: iPhone 17 Pro Max Cosmic Orange 256GB IOS UPDATE | E20: TONYTRENDS | F20: income | G20: PAID | H20: service | J20: 46148
A21: 46148 | B21: SERVICE PROFIT | C21: 5000 | D21: iPhone XR Black 64GB LOCATIN SPOOFING | E21: CUSTOMER | F21: income | G21: PAID | H21: service | J21: 46148
A28: 46148 | B28: USA NUMBER | C28: 29000 | D28: FOR TUNA MONEY USE NUMBER 3 MONTHS | E28: admin | F28: expense | H28: expense
H29: 46149 | I29: PHONE PROFIT | J29: 90000 | K29: Item record_id: 7974dce216f545ce9d88bcc7a36d480b, sale: 820000.00, cost: 730000.00 | L29: admin | M29: income | N29: PAID | O29: phone | P29: 730000 | Q29: 46149
H30: 46149 | I30: PHONE SALE EXPENSE | J30: 2300 | K30: IPHONE 16 P + E | L30: KABEX KAYWISE | M30: expense | O30: expense
H31: 46147 | I31: USA ESIM | J31: 29090 | K31: USA 3 MONTHS ESIM FOR TUNA MONEY | L31: admin | M31: expense | O31: expense
H32: 46149 | I32: SERVICE PROFIT | J32: 2500 | K32: iPhone 14 Pro Max Deep Purple 256GB IOS UPDATE | L32: PERFECT | M32: income | N32: PAID | O32: service | Q32: 46149
H33: 46149 | I33: PHONE PROFIT | J33: 645000 | K33: IPHONE 14 PRO P + E | L33: DON | M33: income | N33: PAID | O33: phone | Q33: 46149
H34: 46149 | I34: SERVICE PROFIT | J34: 2500 | K34: IPHONE 14 PRO SPACE BLACK 128GB IOS UPDATE | L34: DON | M34: income | N34: PAID | O34: service | Q34: 46149
H35: 46149 | I35: SERVICE PROFIT | J35: 2500 | K35: IPHONE 17 PRO MAX IOS UPDATE: ORANGE | L35: DON | M35: income | N35: PAID | O35: service | Q35: 46149
H36: 46149 | I36: SERVICE PROFIT | J36: 5000 | K36: ICLOUD OPENING | L36: DON | M36: income | N36: PAID | O36: service | Q36: 46149
H37: 46149 | I37: SERVICE PROFIT | J37: 3000 | K37: IPHONE 17 PRO MAX SILVER IOS UPDATE | L37: DON | M37: income | N37: PAID | O37: service | Q37: 46149
H38: 46149 | I38: SERVICE PROFIT | J38: 2000 | K38: 2K CASH | L38: DON | M38: income | N38: PAID | O38: service | Q38: 46149
H39: 46149 | I39: PHONE PROFIT | J39: 560000 | K39: IPHONE 15 | L39: SALVAGE YARD | M39: income | N39: PAID | O39: phone | Q39: 46149
H40: 46149 | I40: SERVICE PROFIT | J40: 3000 | K40: SIGNAL TRANSFER | L40: IPRO GADGET | M40: income | N40: PAID | O40: service | Q40: 46149
H41: 46149 | I41: SERVICE EXPENSE | J41: 118150 | K41: IPHONE 16 PLUS FACTORY UNLOCKING | L41: PANKYGEE | M41: expense | O41: expense
H42: 46149 | I42: SERVICE PROFIT | J42: 2500 | K42: PINK 16 IOS UPDATE | L42: MOBILE TRENDS | M42: income | N42: PAID | O42: service | Q42: 46149
H43: 46149 | I43: SERVICE PROFIT | J43: 2500 | K43: IPHONE 16 PLUS TEAL 128GB IOS UPDATE | L43: MOBILE TRENDS | M43: income | N43: PAID | O43: service | Q43: 46149
H44: 46149 | I44: SERVICE PROFIT | J44: 5000 | K44: PICTURES BACKUP AND RESTORE | L44: GNF | M44: income | N44: PAID | O44: service | Q44: 46149
H45: 46149 | I45: SERVICE PROFIT | J45: 10000 | K45: ICLOUD RECOVERY | L45: EMMZY | M45: income | N45: PAID | O45: service | Q45: 46149
H46: 46149 | I46: SERVICE PROFIT | J46: 2500 | K46: IPHONE 13 PRO MAX BATTERY CALIBRATION: GRAPHITE | L46: PANKYGEE | M46: income | N46: PAID | O46: service | Q46: 46149
...

Sheet BACKUP_BILLING_SERVICES
A1: sync_key | B1: record_id | C1: source_hash | D1: sheet_row_num | E1: imei | F1: customer_name | G1: payment_status | H1: payment_date | I1: paid_date | J1: expense_amount | K1: expense_description | L1: calculated_profit | M1: payload_json | N1: created_at | O1: updated_at
A2: 9dcfec929c764ae7a52bfd4caf78d6c5 | B2: 9dcfec929c764ae7a52bfd4caf78d6c5 | C2: 182bd7f4e09edca5570efa1ba87659792e0fcc62d66bae646bb204971c4c6ed8 | D2: 2 | F2: DEMEX | G2: PAID | I2: 2026-02-17T00:00:00+01:00 | J2: 0 | L2: 2500 | M2: {"in":1,"DATE":"2/17/2026","IMEI":"","NAME":"DEMEX","TIME":1,"PRICE":"\u20a62,500.00","STATUS":"paid","PAID DATE":"","RECORD_ID":"9dcfec929c764ae7a52bfd4caf78d6c5","Amount paid":"\u20a62,500.00","DESCRIPTION":"IPHONE 16 BLACK UPDATE","PHONE NUMBER":2347067462101,"DEAL LOCATION":"","INTERNAL NOTE":"","EXPENSE AMOUNT":"","CALCULATED PROFIT":"","EXPENSE DESCRIPTION":"","IMEI FOR SWAPPED DEAL":""} | N2: 2026-05-11T22:24:59.205205+01:00 | O2: 2026-05-11T22:24:59.205205+01:00
A3: e1e76866b2b44537a367a48baed4cbb7 | B3: e1e76866b2b44537a367a48baed4cbb7 | C3: 372f3ec78b24323147b4f700dffe4e8aa3c1d6aeef50adb5615f6d5cf63b3e6a | D3: 3 | F3: DAH UNIQUE | G3: PAID | I3: 2026-02-17T00:00:00+01:00 | J3: 0 | L3: 2500 | M3: {"in":2,"DATE":"2/17/2026","IMEI":"","NAME":"DAH UNIQUE","TIME":2,"PRICE":"\u20a62,500.00","STATUS":"PAID","PAID DATE":"","RECORD_ID":"e1e76866b2b44537a367a48baed4cbb7","Amount paid":"\u20a62,500.00","DESCRIPTION":"GOLD IPHONE 14 PRO","PHONE NUMBER":2349070536253,"DEAL LOCATION":"","INTERNAL NOTE":"","EXPENSE AMOUNT":"","CALCULATED PROFIT":"","EXPENSE DESCRIPTION":"","IMEI FOR SWAPPED DEAL":""} | N3: 2026-05-11T22:00:09.855781+01:00 | O3: 2026-05-11T22:00:09.855781+01:00
A4: 252820e05f6641b4aec1103a18424f72 | B4: 252820e05f6641b4aec1103a18424f72 | C4: 312f2e7e6a48d84f1357c43e5364158446c10ef131b927ada6e57a707cc4207e | D4: 4 | F4: HUNTER LIFE | G4: PAID | I4: 2026-02-17T00:00:00+01:00 | J4: 0 | L4: 185000 | M4: {"in":3,"DATE":"2/17/2026","IMEI":"","NAME":"HUNTER LIFE","TIME":3,"PRICE":"\u20a6185,000.00","STATUS":"PAID","PAID DATE":"","RECORD_ID":"252820e05f6641b4aec1103a18424f72","Amount paid":"\u20a6185,000.00","DESCRIPTION":"SWAPPED IPHONE 13 TO 11 PRO SILVER","PHONE NUMBER":"","DEAL LOCATION":"","INTERNAL NOTE":"","EXPENSE AMOUNT":"","CALCULATED PROFIT":"","EXPENSE DESCRIPTION":"","IMEI FOR SWAPPED DEAL":""} | N4: 2026-05-11T22:00:09.855781+01:00 | O4: 2026-05-11T22:00:09.855781+01:00
A5: 13b8f92dda7b4ff7825daa1e2676f734 | B5: 13b8f92dda7b4ff7825daa1e2676f734 | C5: b342de0a85ca7015b921d37136e8df4efbe26d5ac38b88660361376b52d05439 | D5: 5 | F5: RICKY | G5: PAID | I5: 2026-02-17T00:00:00+01:00 | J5: 0 | L5: 280000 | M5: {"in":4,"DATE":"2/17/2026","IMEI":"","NAME":"RICKY","TIME":4,"PRICE":"\u20a6280,000.00","STATUS":"PAID","PAID DATE":"","RECORD_ID":"13b8f92dda7b4ff7825daa1e2676f734","Amount paid":"\u20a6280,000.00","DESCRIPTION":"IPHONE 16 PRO GOLD 100% SWAPPED WITH IPHONE 15 PRO 512GB","PHONE NUMBER":"","DEAL LOCATION":"","INTERNAL NOTE":"","EXPENSE AMOUNT":"","CALCULATED PROFIT":"","EXPENSE DESCRIPTION":"","IMEI FOR SWAPPED DEAL":""} | N5: 2026-05-11T22:00:09.855781+01:00 | O5: 2026-05-11T22:00:09.855781+01:00
A6: c2a8339184ce430f975db6123c51a7fb | B6: c2a8339184ce430f975db6123c51a7fb | C6: 04433d211be85f3310bc12392fe78ad9267c483d15f928cfeedd6495fe0c0099 | D6: 6 | F6: OSES | G6: PAID | I6: 2026-02-17T00:00:00+01:00 | J6: 0 | L6: 2500 | M6: {"in":5,"DATE":"2/17/2026","IMEI":"","NAME":"OSES","TIME":5,"PRICE":"\u20a62,500.00","STATUS":"PAID","PAID DATE":"","RECORD_ID":"c2a8339184ce430f975db6123c51a7fb","Amount paid":"\u20a62,500.00","DESCRIPTION":"IPHONE 14 PLUS UPDATE MIDNIGHT COLOR","PHONE NUMBER":"","DEAL LOCATION":"","INTERNAL NOTE":"","EXPENSE AMOUNT":"","CALCULATED PROFIT":"","EXPENSE DESCRIPTION":"","IMEI FOR SWAPPED DEAL":""} | N6: 2026-05-11T22:00:09.855781+01:00 | O6: 2026-05-11T22:00:09.855781+01:00
A7: 3debc2aabaa842ce9d440b9b84980f2d | B7: 3debc2aabaa842ce9d440b9b84980f2d | C7: 1cf3d8e50fa7d4466cfac22718dad2a957bc970ef8057e8e7bd5c07b6f68c88e | D7: 7 | F7: KEMI FROM SEUN | G7: PAID | I7: 2026-02-17T00:00:00+01:00 | J7: 0 | L7: 1500000 | M7: {"in":6,"DATE":"2/17/2026","IMEI":"","NAME":"KEMI FROM SEUN","TIME":6,"PRICE":"\u20a61,500,000.00","STATUS":"PAID","PAID DATE":"","RECORD_ID":"3debc2aabaa842ce9d440b9b84980f2d","Amount paid":"\u20a61,500,000.00","DESCRIPTION":"IPHONE 15 PRO MAX 512GB TO IPHONE ","PHONE NUMBER":"","DEAL LOCATION":"","INTERNAL NOTE":"","EXPENSE AMOUNT":"","CALCULATED PROFIT":"","EXPENSE DESCRIPTION":"","IMEI FOR SWAPPED DEAL":""} | N7: 2026-05-11T22:00:09.855781+01:00 | O7: 2026-05-11T22:00:09.855781+01:00
A8: ad63bb932f7e47abb64bae4d1546a4d8 | B8: ad63bb932f7e47abb64bae4d1546a4d8 | C8: a72c6adfd6571cb40c0e58670dcaca91f1237ed0dce6b37b07fa2bced7ab1d89 | D8: 8 | F8: IBIRONKE FAVOUR | G8: PAID | I8: 2026-02-17T00:00:00+01:00 | J8: 0 | L8: 10000 | M8: {"in":7,"DATE":"2/17/2026","IMEI":"","NAME":"IBIRONKE FAVOUR","TIME":7,"PRICE":"\u20a610,000.00","STATUS":"PAID","PAID DATE":"","RECORD_ID":"ad63bb932f7e47abb64bae4d1546a4d8","Amount paid":"\u20a610,000.00","DESCRIPTION":"APPLE ID CREATE & SIGN IN","PHONE NUMBER":"","DEAL LOCATION":"","INTERNAL NOTE":"","EXPENSE AMOUNT":"","CALCULATED PROFIT":"","EXPENSE DESCRIPTION":"","IMEI FOR SWAPPED DEAL":""} | N8: 2026-05-11T22:00:09.855781+01:00 | O8: 2026-05-11T22:00:09.855781+01:00
A9: ff964ae5a2f2444187915c0d21934773 | B9: ff964ae5a2f2444187915c0d21934773 | C9: fa6f408304c6f398b59360e9e27e83e1473c89e0742d62036655e231c564f9bf | D9: 9 | F9: CLINTON GADGET | G9: PAID | I9: 2026-02-17T00:00:00+01:00 | J9: 0 | L9: 800000 | M9: {"in":8,"DATE":"2/17/2026","IMEI":"","NAME":"CLINTON GADGET","TIME":8,"PRICE":"\u20a6800,000.00","STATUS":"PAID","PAID DATE":"","RECORD_ID":"ff964ae5a2f2444187915c0d21934773","Amount paid":"\u20a6800,000.00","DESCRIPTION":"IPHONE 16 256GB 354178509660284","PHONE NUMBER":"","DEAL LOCATION":"","INTERNAL NOTE":"","EXPENSE AMOUNT":"","CALCULATED PROFIT":"","EXPENSE DESCRIPTION":"","IMEI FOR SWAPPED DEAL":""} | N9: 2026-05-11T22:00:09.855781+01:00 | O9: 2026-05-11T22:00:09.855781+01:00
A10: fb2d541894b74a0a9fcffa10378d8580 | B10: fb2d541894b74a0a9fcffa10378d8580 | C10: 752ed674e7c3e5b952090af84d410bfe0c4b4399c82e0b2f2372f6fc655ed8d4 | D10: 10 | F10: NURUDEEN | G10: PAID | I10: 2026-02-17T00:00:00+01:00 | J10: 0 | L10: 25000 | M10: {"in":9,"DATE":"2/17/2026","IMEI":"","NAME":"NURUDEEN","TIME":9,"PRICE":"\u20a625,000.00","STATUS":"PAID","PAID DATE":"","RECORD_ID":"fb2d541894b74a0a9fcffa10378d8580","Amount paid":"\u20a625,000.00","DESCRIPTION":"CHIP FOR IPHONE 12 PRO PACIFIC BLUE","PHONE NUMBER":9122727950,"DEAL LOCATION":"","INTERNAL NOTE":"","EXPENSE AMOUNT":"","CALCULATED PROFIT":"","EXPENSE DESCRIPTION":"","IMEI FOR SWAPPED DEAL":""} | N10: 2026-05-11T22:00:09.855781+01:00 | O10: 2026-05-11T22:00:09.855781+01:00
A11: 38425b848c1e4f8195ec6df4938be5ca | B11: 38425b848c1e4f8195ec6df4938be5ca | C11: abc1305ba32ad02576483dce4e9c28a4a3b2c1b92f2cace07e66d83d0f3b96f9 | D11: 11 | F11: WIZZY | G11: PAID | I11: 2026-02-17T00:00:00+01:00 | J11: 0 | L11: 2500 | M11: {"in":10,"DATE":"2/17/2026","IMEI":"","NAME":"WIZZY","TIME":10,"PRICE":"\u20a62,500.00","STATUS":"PAID","PAID DATE":"","RECORD_ID":"38425b848c1e4f8195ec6df4938be5ca","Amount paid":"\u20a62,500.00","DESCRIPTION":"NATURAL TITANIUM IPHONE 15 PRO MAX IOS UPDATE","PHONE NUMBER":2348108686713,"DEAL LOCATION":"","INTERNAL NOTE":"","EXPENSE AMOUNT":"","CALCULATED PROFIT":"","EXPENSE DESCRIPTION":"","IMEI FOR SWAPPED DEAL":""} | N11: 2026-05-11T22:00:09.855781+01:00 | O11: 2026-05-11T22:00:09.855781+01:00
A12: 7f9250f3a89542a69db22bdb2807f36b | B12: 7f9250f3a89542a69db22bdb2807f36b | C12: cc53046a2b49f5d4ad8aa9e79267f3851b15ee26ac8a813f9a3a35657598cd51 | D12: 12 | F12: ZEE TECH | G12: PAID | I12: 2026-02-15T00:00:00+01:00 | J12: 0 | L12: 2500 | M12: {"in":11,"DATE":"2/15/2026","IMEI":"","NAME":"ZEE TECH","TIME":11,"PRICE":"\u20a62,500.00","STATUS":"PAID","PAID DATE":"","RECORD_ID":"7f9250f3a89542a69db22bdb2807f36b","Amount paid":"\u20a62,500.00","DESCRIPTION":"IPHONE 13 IOS UPDATE ","PHONE NUMBER":2349033724061,"DEAL LOCATION":"","INTERNAL NOTE":"","EXPENSE AMOUNT":"","CALCULATED PROFIT":"","EXPENSE DESCRIPTION":"","IMEI FOR SWAPPED DEAL":""} | N12: 2026-05-11T22:00:09.855781+01:00 | O12: 2026-05-11T22:00:09.855781+01:00
A13: c8dc8dfa28c343c484a7f2ba7fbf5b3f | B13: c8dc8dfa28c343c484a7f2ba7fbf5b3f | C13: 0f2f93f4f889a4fde8c557267248a9bea0311aff0d24971f6bf1788d8543f881 | D13: 13 | F13: ZEE TECH | G13: PAID | I13: 2026-02-16T00:00:00+01:00 | J13: 0 | L13: 2500 | M13: {"in":12,"DATE":"2/16/2026","IMEI":"","NAME":"ZEE TECH","TIME":12,"PRICE":"\u20a62,500.00","STATUS":"PAID","PAID DATE":"","RECORD_ID":"c8dc8dfa28c343c484a7f2ba7fbf5b3f","Amount paid":"\u20a62,500.00","DESCRIPTION":"IPHONE 13 PRO MAX IOS UPDATE","PHONE NUMBER":2349033724061,"DEAL LOCATION":"","INTERNAL NOTE":"","EXPENSE AMOUNT":"","CALCULATED PROFIT":"","EXPENSE DESCRIPTION":"","IMEI FOR SWAPPED DEAL":""} | N13: 2026-05-11T22:00:09.855781+01:00 | O13: 2026-05-11T22:00:09.855781+01:00
... A24: 4590d23eb8fa43579501fbc6bd071bd1 | B24: 4590d23eb8fa43579501fbc6bd071bd1 | C24: 7406a1cd32b6bd330690fccbe8eb52b7e7dcdbc585eabec1cff4b8f9210026b3 | D24: 24 | F24: VERTEX | G24: PAID | I24: 2026-02-07T00:00:00+01:00 | J24: 0 | L24: 2500 | M24: {"in":23,"DATE":"2/7/2026","IMEI":"","NAME":"VERTEX","TIME":7,"PRICE":"\u20a62,500.00","STATUS":"PAID","PAID DATE":"","RECORD_ID":"4590d23eb8fa43579501fbc6bd071bd1","Amount paid":"","DESCRIPTION":"PINK IPHONE 15 PLUS UPDATE","PHONE NUMBER":2348103663581,"DEAL LOCATION":"","INTERNAL NOTE":"","EXPENSE AMOUNT":"","CALCULATED PROFIT":"","EXPENSE DESCRIPTION":"","IMEI FOR SWAPPED DEAL":""} | N24: 2026-05-11T22:00:09.855781+01:00 | O24: 2026-05-11T22:00:09.855781+01:00
A25: 9bbbf52992df41bca266eeb13d53ad91 | B25: 9bbbf52992df41bca266eeb13d53ad91 | C25: 5b6345f98ee7ddc5975f7556450e58fa26488177d5bf12fb500cace71f7c0771 | D25: 25 | F25: MIKKY | G25: RETURNED | J25: 0 | L25: 0 | M25: {"in":24,"DATE":"2/7/2026","IMEI":"","NAME":"MIKKY","TIME":8,"PRICE":"\u20a620,000.00","STATUS":"RETURNED","PAID DATE":"","RECORD_ID":"9bbbf52992df41bca266eeb13d53ad91","Amount paid":"","DESCRIPTION":"IPHONE 13 PRO MAX CHIP","PHONE NUMBER":"","DEAL LOCATION":"","INTERNAL NOTE":"","EXPENSE AMOUNT":"","CALCULATED PROFIT":"","EXPENSE DESCRIPTION":"","IMEI FOR SWAPPED DEAL":""} | N25: 2026-05-11T22:00:09.855781+01:00 | O25: 2026-05-11T22:00:09.855781+01:00
A26: f902b4c8ea8c49a2bdb4466ed2b99884 | B26: f902b4c8ea8c49a2bdb4466ed2b99884 | C26: b44bb2a34ad93d59d783d069cbb33ac5913e4e6d2c23c5ab3467462aa4146e05 | D26: 26 | F26: PRINZE GADGET | G26: PAID | I26: 2026-02-07T00:00:00+01:00 | J26: 0 | L26: 2500 | M26: {"in":25,"DATE":"2/7/2026","IMEI":"","NAME":"PRINZE GADGET","TIME":9,"PRICE":"\u20a62,500.00","STATUS":"PAID","PAID DATE":"","RECORD_ID":"f902b4c8ea8c49a2bdb4466ed2b99884","Amount paid":"","DESCRIPTION":"IPHONE 13 UPDATE","PHONE NUMBER":"","DEAL LOCATION":"","INTERNAL NOTE":"","EXPENSE AMOUNT":"","CALCULATED PROFIT":"","EXPENSE DESCRIPTION":"","IMEI FOR SWAPPED DEAL":""} | N26: 2026-05-11T22:00:09.855781+01:00 | O26: 2026-05-11T22:00:09.855781+01:00
A27: c6f548765acd4277a3081301ea7558e0 | B27: c6f548765acd4277a3081301ea7558e0 | C27: aa2d1a016de77c6be26beb0db821c23e89ea727afecb9edb748679048b20bd7f | D27: 27 | F27: DENIS4WARD | G27: PAID | I27: 2026-02-05T00:00:00+01:00 | J27: 0 | L27: 225000 | M27: {"in":26,"DATE":"2/5/2026","IMEI":"","NAME":"DENIS4WARD","TIME":10,"PRICE":"\u20a6225,000.00","STATUS":"PAID","PAID DATE":"","RECORD_ID":"c6f548765acd4277a3081301ea7558e0","Amount paid":"","DESCRIPTION":"PS4 SLIM AND ONE GAMEPAD","PHONE NUMBER":2348038551439,"DEAL LOCATION":"","INTERNAL NOTE":"","EXPENSE AMOUNT":"","CALCULATED PROFIT":"","EXPENSE DESCRIPTION":"","IMEI FOR SWAPPED DEAL":""} | N27: 2026-05-11T22:00:09.855781+01:00 | O27: 2026-05-11T22:00:09.855781+01:00
A28: 1a175228683e4c7f83fa4ff7d78edd6c | B28: 1a175228683e4c7f83fa4ff7d78edd6c | C28: 740495f672b7b4c2891484bb2dc5878d1a23c225e75c0475fda8e0cea4ea8514 | D28: 28 | F28: MIDE GADGET | G28: PAID | I28: 2026-02-04T00:00:00+01:00 | J28: 0 | L28: 2500 | M28: {"in":27,"DATE":"2/4/2026","IMEI":"","NAME":"MIDE GADGET","TIME":11,"PRICE":"\u20a62,500.00","STATUS":"PAID","PAID DATE":"","RECORD_ID":"1a175228683e4c7f83fa4ff7d78edd6c","Amount paid":"","DESCRIPTION":"BLUE IPHONE 16 UPDATE","PHONE NUMBER":"","DEAL LOCATION":"","INTERNAL NOTE":"","EXPENSE AMOUNT":"","CALCULATED PROFIT":"","EXPENSE DESCRIPTION":"","IMEI FOR SWAPPED DEAL":""} | N28: 2026-05-11T22:00:09.855781+01:00 | O28: 2026-05-11T22:00:09.855781+01:00
A29: cfb45f1f05604357b7eca2af401cc1b6 | B29: cfb45f1f05604357b7eca2af401cc1b6 | C29: 2a50123134633308eebf7031c4989b9feda4911c49226f101627a6108a8f921e | D29: 29 | F29: ZADDY ROLLAND | G29: PENDING | J29: 0 | L29: 0 | M29: {"in":28,"DATE":"2/3/2026","IMEI":"","NAME":"ZADDY ROLLAND","TIME":12,"PRICE":"\u20a6450,000.00","STATUS":"PENDING","PAID DATE":"","RECORD_ID":"cfb45f1f05604357b7eca2af401cc1b6","Amount paid":"","DESCRIPTION":"TEAL 16 P+E BALANCE","PHONE NUMBER":2348050554029,"DEAL LOCATION":"","INTERNAL NOTE":"","EXPENSE AMOUNT":"","CALCULATED PROFIT":"","EXPENSE DESCRIPTION":"","IMEI FOR SWAPPED DEAL":""} | N29: 2026-05-11T22:00:09.855781+01:00 | O29: 2026-05-11T22:00:09.855781+01:00
A30: 08f797e6e883406aafbd18de33d0fe07 | B30: 08f797e6e883406aafbd18de33d0fe07 | C30: 5b580a6a615ab9873d8276cd7c915dada1eee55df93b2927f2758553d0952aeb | D30: 30 | F30: ZADDY ROLLAND | G30: UNPAID | J30: 0 | L30: 0 | M30: {"in":29,"DATE":"2/3/2026","IMEI":"","NAME":"ZADDY ROLLAND","TIME":13,"PRICE":"\u20a62,500.00","STATUS":"UNPAID","PAID DATE":"","RECORD_ID":"08f797e6e883406aafbd18de33d0fe07","Amount paid":"","DESCRIPTION":"TEAL 16 P+E UPDATE","PHONE NUMBER":2348050554029,"DEAL LOCATION":"","INTERNAL NOTE":"","EXPENSE AMOUNT":"","CALCULATED PROFIT":"","EXPENSE DESCRIPTION":"","IMEI FOR SWAPPED DEAL":""} | N30: 2026-05-11T22:00:09.855781+01:00 | O30: 2026-05-11T22:00:09.855781+01:00
A31: 19d21d47029d41d0af0fc380928ba2cb | B31: 19d21d47029d41d0af0fc380928ba2cb | C31: 49a74b47836baff80a3ab73ab966b0431f06e0f0d0285985a895073c58730bf7 | D31: 31 | F31: JAMEX | G31: PENDING | J31: 0 | L31: 0 | M31: {"in":30,"DATE":"2/18/2026","IMEI":"","NAME":"JAMEX","TIME":14,"PRICE":"\u20a6395,000.00","STATUS":"PENDING","PAID DATE":"","RECORD_ID":"19d21d47029d41d0af0fc380928ba2cb","Amount paid":"","DESCRIPTION":"OUTSTANDING BALANCE","PHONE NUMBER":2347033260364,"DEAL LOCATION":"","INTERNAL NOTE":"","EXPENSE AMOUNT":"","CALCULATED PROFIT":"","EXPENSE DESCRIPTION":"","IMEI FOR SWAPPED DEAL":""} | N31: 2026-05-11T22:00:09.855781+01:00 | O31: 2026-05-11T22:00:09.855781+01:00
A32: ee70de5352b248dda16ed018caac6dab | B32: ee70de5352b248dda16ed018caac6dab | C32: ecefa2e26506ec3543ff677bbadafac492e6e1c1d27bd2d7f1f30b4c499b311b | D32: 32 | F32: AYANFE | G32: PAID | I32: 2026-01-28T00:00:00+01:00 | J32: 0 | L32: 10000 | M32: {"in":31,"DATE":"1/28/2026","IMEI":"","NAME":"AYANFE","TIME":15,"PRICE":"\u20a610,000.00","STATUS":"PAID","PAID DATE":"","RECORD_ID":"ee70de5352b248dda16ed018caac6dab","Amount paid":"","DESCRIPTION":"APPLE ID RECOVERY","PHONE NUMBER":2348138108648,"DEAL LOCATION":"","INTERNAL NOTE":"","EXPENSE AMOUNT":"","CALCULATED PROFIT":"","EXPENSE DESCRIPTION":"","IMEI FOR SWAPPED DEAL":""} | N32: 2026-05-11T22:00:09.855781+01:00 | O32: 2026-05-11T22:00:09.855781+01:00
A33: 1e7c1962321a484b82cda53c4bbc338e | B33: 1e7c1962321a484b82cda53c4bbc338e | C33: 616bd1ccc1d6fd6c67dda5cdca62cd727478c4901be9bf360d93028d1a0cd732 | D33: 33 | F33: DENIS4WARD | G33: PAID | I33: 2026-01-27T00:00:00+01:00 | J33: 0 | L33: 5000 | M33: {"in":32,"DATE":"1/27/2026","IMEI":"","NAME":"DENIS4WARD","TIME":16,"PRICE":"\u20a65,000.00","STATUS":"PAID","PAID DATE":"","RECORD_ID":"1e7c1962321a484b82cda53c4bbc338e","Amount paid":"","DESCRIPTION":"ILESHA DRIVER","PHONE NUMBER":2348038551439,"DEAL LOCATION":"","INTERNAL NOTE":"","EXPENSE AMOUNT":"","CALCULATED PROFIT":"","EXPENSE DESCRIPTION":"","IMEI FOR SWAPPED DEAL":""} | N33: 2026-05-11T22:00:09.855781+01:00 | O33: 2026-05-11T22:00:09.855781+01:00
A34: 523b7a62015f4f16aaa6fdcfe135e889 | B34: 523b7a62015f4f16aaa6fdcfe135e889 | C34: eb97ad278df237441a3c5555308dbe623d8176cc6ee1491f5f33a84170fa3b39 | D34: 34 | E34: 356295374969208 | F34: PRINZE GADGETS | G34: PAID | I34: 2026-01-27T00:00:00+01:00 | J34: 0 | L34: 280000 | M34: {"in":"","DATE":"1/27/2026","IMEI":356295374969208,"NAME":"PRINZE GADGETS","TIME":17,"PRICE":"\u20a6280,000.00","STATUS":"PAID","PAID DATE":"","RECORD_ID":"523b7a62015f4f16aaa6fdcfe135e889","Amount paid":"","DESCRIPTION":"MIDNIGET LOCKED 14 PLUS. 81%","PHONE NUMBER":2348073229131,"DEAL LOCATION":"","INTERNAL NOTE":"","EXPENSE AMOUNT":"","CALCULATED PROFIT":"","EXPENSE DESCRIPTION":"","IMEI FOR SWAPPED DEAL":""} | N34: 2026-05-11T22:00:09.855781+01:00 | O34: 2026-05-11T22:00:09.855781+01:00
A35: 69bdbb71ddb34659b3c51ffc3f27914b | B35: 69bdbb71ddb34659b3c51ffc3f27914b | C35: f6a2b0a479da4c76351c87230b72fd1b3862b5d7ae3ad20f855d2c437af8b5a6 | D35: 35 | F35: DENIS4WARD | G35: PAID | I35: 2026-01-27T00:00:00+01:00 | J35: 0 | L35: 16250 | M35: {"in":33,"DATE":"1/27/2026","IMEI":"","NAME":"DENIS4WARD","TIME":18,"PRICE":"\u20a616,250.00","STATUS":"PAID","PAID DATE":"","RECORD_ID":"69bdbb71ddb34659b3c51ffc3f27914b","Amount paid":"","DESCRIPTION":"GAS FILL","PHONE NUMBER":2348038551439,"DEAL LOCATION":"","INTERNAL NOTE":"","EXPENSE AMOUNT":"","CALCULATED PROFIT":"","EXPENSE DESCRIPTION":"","IMEI FOR SWAPPED DEAL":""} | N35: 2026-05-11T22:00:09.855781+01:00 | O35: 2026-05-11T22:00:09.855781+01:00
A36: 259c651fb2fc45bea1649447a37d344c | B36: 259c651fb2fc45bea1649447a37d344c | C36: 334c799d74c2440de1ec4bb963fc655a4aa3d5224833622a72a25ab03f186612 | D36: 36 | E36: .. | F36: .. | J36: 0 | L36: 0 | M36: {"in":34,"DATE":"..","IMEI":"..","NAME":"..","TIME":"..","PRICE":"..","STATUS":"","PAID DATE":"","RECORD_ID":"259c651fb2fc45bea1649447a37d344c","Amount paid":"","DESCRIPTION":"..","PHONE NUMBER":"","DEAL LOCATION":"","INTERNAL NOTE":"","EXPENSE AMOUNT":"","CALCULATED PROFIT":"","EXPENSE DESCRIPTION":"","IMEI FOR SWAPPED DEAL":""} | N36: 2026-05-11T22:00:09.855781+01:00 | O36: 2026-05-11T22:00:09.855781+01:00
A37: 3a3ee298459f443e97ad50509eb0e3dd | B37: 3a3ee298459f443e97ad50509eb0e3dd | C37: 6e96988d2e8f6e42c38bb194995f9da7ebebe4a4b0eb706d605d7beaac7a767b | D37: 37 | F37: NURUDEEN | G37: PAID | I37: 2026-02-18T00:00:00+01:00 | J37: 0 | L37: 2500 | M37: {"in":35,"DATE":"2/18/2026","IMEI":"","NAME":"NURUDEEN","TIME":1,"PRICE":"\u20a62,500.00","STATUS":"PAID","PAID DATE":"","RECORD_ID":"3a3ee298459f443e97ad50509eb0e3dd","Amount paid":"","DESCRIPTION":"NATURAL TITANIUM 15 PRO UPDATE","PHONE NUMBER":9122727950,"DEAL LOCATION":"","INTERNAL NOTE":"","EXPENSE AMOUNT":"","CALCULATED PROFIT":"","EXPENSE DESCRIPTION":"","IMEI FOR SWAPPED DEAL":""} | N37: 2026-05-11T22:00:09.855781+01:00 | O37: 2026-05-11T22:00:09.855781+01:00
A38: 860f6063e1f64ed69181fea34c1331b6 | B38: 860f6063e1f64ed69181fea34c1331b6 | C38: bc4b08c1ef7d6185d7c8aaaf1b46ac32f88fe32a2e8b0ee6e29458329da13aef | D38: 38 | F38: DAMBOX | G38: PAID | I38: 2026-02-18T00:00:00+01:00 | J38: 0 | L38: 2500 | M38: {"in":36,"DATE":"2/18/2026","IMEI":"","NAME":"DAMBOX","TIME":2,"PRICE":"\u20a62,500.00","STATUS":"PAID","PAID DATE":"","RECORD_ID":"860f6063e1f64ed69181fea34c1331b6","Amount paid":"","DESCRIPTION":"ORANGE IPHONE 17 PRO IOS UPDATE","PHONE NUMBER":9040943517,"DEAL LOCATION":"","INTERNAL NOTE":"","EXPENSE AMOUNT":"","CALCULATED PROFIT":"","EXPENSE DESCRIPTION":"","IMEI FOR SWAPPED DEAL":""} | N38: 2026-05-11T22:00:09.855781+01:00 | O38: 2026-05-11T22:00:09.855781+01:00
A39: b263752956ea49d493083d288125523d | B39: b263752956ea49d493083d288125523d | C39: b0b5106a9951fc9542fff4536d761f739c44551d5ff25b3eb1f1f70556ba31de | D39: 39 | F39: KAYWISE | G39: PAID | I39: 2026-02-18T00:00:00+01:00 | J39: 0 | L39: 2000 | M39: {"in":37,"DATE":"2/18/2026","IMEI":"","NAME":"KAYWISE","TIME":3,"PRICE":"\u20a62,000.00","STATUS":"PAID","PAID DATE":"","RECORD_ID":"b263752956ea49d493083d288125523d","Amount paid":"\u20a62,000.00","DESCRIPTION":"ULTRAMARINE IPHONE 16 PLUS UPDATE","PHONE NUMBER":2349032614464,"DEAL LOCATION":"","INTERNAL NOTE":"","EXPENSE AMOUNT":"","CALCULATED PROFIT":"","EXPENSE DESCRIPTION":"","IMEI FOR SWAPPED DEAL":""} | N39: 2026-05-11T22:00:09.855781+01:00 | O39: 2026-05-11T22:00:09.855781+01:00
A40: 1cbe6952e28545e786673dbdbb797adf | B40: 1cbe6952e28545e786673dbdbb797adf | C40: aac2441f94784d902fac74d40ecd85f515a23623a7d3d872d65e137f0f5e4acb | D40: 40 | F40: PANKEY | G40: PAID | I40: 2026-02-18T00:00:00+01:00 | J40: 0 | L40: 2500 | M40: {"in":38,"DATE":"2/18/2026","IMEI":"","NAME":"PANKEY","TIME":4,"PRICE":"\u20a62,500.00","STATUS":"PAID","PAID DATE":"","RECORD_ID":"1cbe6952e28545e786673dbdbb797adf","Amount paid":"","DESCRIPTION":"WHITE IPHONE 15 FIX BATTERY FLASH","PHONE NUMBER":"","DEAL LOCATION":"","INTERNAL NOTE":"","EXPENSE AMOUNT":"","CALCULATED PROFIT":"","EXPENSE DESCRIPTION":"","IMEI FOR SWAPPED DEAL":""} | N40: 2026-05-11T22:00:09.855781+01:00 | O40: 2026-05-11T22:00:09.855781+01:00
A41: bf9eb880a87d40c59d132b0de1fa1c21 | B41: bf9eb880a87d40c59d132b0de1fa1c21 | C41: 9fc8fe6c46c7f3e3e44fcb16779f5e20e18f0e3e3b46d9c99fabd6d046a63c57 | D41: 41 | F41: THANKGOD | G41: PAID | I41: 2026-02-18T00:00:00+01:00 | J41: 0 | L41: 380000 | M41: {"in":39,"DATE":"2/18/2026","IMEI":"","NAME":"THANKGOD","TIME":5,"PRICE":"\u20a6380,000.00","STATUS":"PAID","PAID DATE":"","RECORD_ID":"bf9eb880a87d40c59d132b0de1fa1c21","Amount paid":"","DESCRIPTION":"IPHONE 16 ROUGH BODY SWAPPED WITH IPHONE 15 PTO MAX LOCKED NATURAL TITANIUM","PHONE NUMBER":"","DEAL LOCATION":"","INTERNAL NOTE":"","EXPENSE AMOUNT":"","CALCULATED PROFIT":"","EXPENSE DESCRIPTION":"","IMEI FOR SWAPPED DEAL":""} | N41: 2026-05-11T22:00:09.855781+01:00 | O41: 2026-05-11T22:00:09.855781+01:00
A42: 1fb7ef6836d24151a7f090a42d18e786 | B42: 1fb7ef6836d24151a7f090a42d18e786 | C42: e4858f20b221f4b149a42a29917c1cbf62c73ee7b0d60e6f5ef278b4a4797bda | D42: 42 | F42: JAYJOSH | G42: PAID | I42: 2026-02-18T00:00:00+01:00 | J42: 0 | L42: 10000 | M42: {"in":40,"DATE":"2/18/2026","IMEI":"","NAME":"JAYJOSH","TIME":6,"PRICE":"\u20a610,000.00","STATUS":"PAID","PAID DATE":"","RECORD_ID":"1fb7ef6836d24151a7f090a42d18e786","Amount paid":"","DESCRIPTION":"CHIP FIX IPHONE 13","PHONE NUMBER":"","DEAL LOCATION":"","INTERNAL NOTE":"","EXPENSE AMOUNT":"","CALCULATED PROFIT":"","EXPENSE DESCRIPTION":"","IMEI FOR SWAPPED DEAL":""} | N42: 2026-05-11T22:00:09.855781+01:00 | O42: 2026-05-11T22:00:09.855781+01:00
A43: 303affb6d32d4981b8b8fedc73b99291 | B43: 303affb6d32d4981b8b8fedc73b99291 | C43: 0e9bf5289070a1804b3d3f304e0c0deb319aae94530b4c03fbf7912adbb3c30d | D43: 43 | F43: BIGGIE - MELTRONICS | G43: PAID | I43: 2026-02-18T00:00:00+01:00 | J43: 0 | L43: 290000 | M43: {"in":41,"DATE":"2/18/2026","IMEI":"","NAME":"BIGGIE - MELTRONICS","TIME":7,"PRICE":"\u20a6290,000.00","STATUS":"PAID","PAID DATE":"","RECORD_ID":"303affb6d32d4981b8b8fedc73b99291","Amount paid":"","DESCRIPTION":"HP PAVILION 1TB HDD","PHONE NUMBER":"","DEAL LOCATION":"","INTERNAL NOTE":"","EXPENSE AMOUNT":"","CALCULATED PROFIT":"","EXPENSE DESCRIPTION":"","IMEI FOR SWAPPED DEAL":""} | N43: 2026-05-11T22:00:09.855781+01:00 | O43: 2026-05-11T22:00:09.855781+01:00
A44: 659a57f80bc94538946b864ec33870e7 | B44: 659a57f80bc94538946b864ec33870e7 | C44: 51eec0e370719d946db4b415be10d322cf25393e2a51dd24b7f3595500881135 | D44: 44 | F44: EMPEROR CORPER | G44: PAID | I44: 2026-02-18T00:00:00+01:00 | J44: 0 | L44: 3000 | M44: {"in":42,"DATE":"2/18/2026","IMEI":"","NAME":"EMPEROR CORPER","TIME":8,"PRICE":"\u20a63,000.00","STATUS":"PAID","PAID DATE":"","RECORD_ID":"659a57f80bc94538946b864ec33870e7","Amount paid":"","DESCRIPTION":"SUPERBIKE MAN DISPATCH TO ENGINEER ISAAC","PHONE NUMBER":"","DEAL LOCATION":"","INTERNAL NOTE":"","EXPENSE AMOUNT":"","CALCULATED PROFIT":"","EXPENSE DESCRIPTION":"","IMEI FOR SWAPPED DEAL":""} | N44: 2026-05-11T22:00:09.855781+01:00 | O44: 2026-05-11T22:00:09.855781+01:00
A45: b1f5c60eb3504112b40d0c61a6075916 | B45: b1f5c60eb3504112b40d0c61a6075916 | C45: d13ee6bfa23a1a7c7929a25376a547a0aa86c35aea58b391917d4ed09be4eeb2 | D45: 45 | F45: OLLY | G45: PAID | I45: 2026-02-18T00:00:00+01:00 | J45: 0 | L45: 35000 | M45: {"in":43,"DATE":"2/18/2026","IMEI":"","NAME":"OLLY","TIME":9,"PRICE":"\u20a635,000.00","STATUS":"PAID","PAID DATE":"","RECORD_ID":"b1f5c60eb3504112b40d0c61a6075916","Amount paid":"","DESCRIPTION":"ESIM 1 MONTH","PHONE NUMBER":"","DEAL LOCATION":"","INTERNAL NOTE":"","EXPENSE AMOUNT":"","CALCULATED PROFIT":"","EXPENSE DESCRIPTION":"","IMEI FOR SWAPPED DEAL":""} | N45: 2026-05-11T22:00:09.855781+01:00 | O45: 2026-05-11T22:00:09.855781+01:00
A46: 11f19a7f43ff44c189d963304bd3b32c | B46: 11f19a7f43ff44c189d963304bd3b32c | C46: 6e5c6a93c7dd072b1cfeed890b5a2665134dda07d9b3ef9d502101781cfa9e39 | D46: 46 | F46: DENIS4WARD | G46: PAID | I46: 2025-11-14T00:00:00+01:00 | J46: 0 | L46: 40000 | M46: {"in":44,"DATE":"11/14/2025","IMEI":"","NAME":"DENIS4WARD","TIME":10,"PRICE":"\u20a640,000.00","STATUS":"PAID","PAID DATE":"","RECORD_ID":"11f19a7f43ff44c189d963304bd3b32c","Amount paid":"","DESCRIPTION":"CONVOCATION DRINK","PHONE NUMBER":2348038551439,"DEAL LOCATION":"","INTERNAL NOTE":"","EXPENSE AMOUNT":"","CALCULATED PROFIT":"","EXPENSE DESCRIPTION":"","IMEI FOR SWAPPED DEAL":""} | N46: 2026-05-11T22:00:09.855781+01:00 | O46: 2026-05-11T22:00:09.855781+01:00
A47: b5279189300d42909bff74710f3f263a | B47: b5279189300d42909bff74710f3f263a | C47: 6eead6b54d6ee72159e37bc6d628df8a2cae07028ed5996104446be801dcbb71 | D47: 47 | F47: DENIS4WARD | G47: PAID | I47: 2026-01-13T00:00:00+01:00 | J47: 0 | L47: 16250 | M47: {"in":"","DATE":"1/13/2026","IMEI":"","NAME":"DENIS4WARD","TIME":11,"PRICE":"\u20a616,250.00","STATUS":"PAID","PAID DATE":"","RECORD_ID":"b5279189300d42909bff74710f3f263a","Amount paid":"","DESCRIPTION":"GAS FILL","PHONE NUMBER":2348038551439,"DEAL LOCATION":"","INTERNAL NOTE":"","EXPENSE AMOUNT":"","CALCULATED PROFIT":"","EXPENSE DESCRIPTION":"","IMEI FOR SWAPPED DEAL":""} | N47: 2026-05-11T22:00:09.855781+01:00 | O47: 2026-05-11T22:00:09.855781+01:00
A48: 99aa324644f94ceea7045ff30a389a90 | B48: 99aa324644f94ceea7045ff30a389a90 | C48: 94e699455683858ebfad3f296dee43141ee5c15cb2a8ac3887fa1e27045fbcfc | D48: 48 | E48: .. | F48: .. | G48: .. | J48: 0 | L48: 0 | M48: {"in":45,"DATE":"..","IMEI":"..","NAME":"..","TIME":"","PRICE":"..","STATUS":"..","PAID DATE":"","RECORD_ID":"99aa324644f94ceea7045ff30a389a90","Amount paid":"","DESCRIPTION":"..","PHONE NUMBER":"","DEAL LOCATION":"","INTERNAL NOTE":"","EXPENSE AMOUNT":"","CALCULATED PROFIT":"","EXPENSE DESCRIPTION":"","IMEI FOR SWAPPED DEAL":""} | N48: 2026-05-11T22:00:09.855781+01:00 | O48: 2026-05-11T22:00:09.855781+01:00
A49: 77b5d09c077f4d6bb71031d0575f0baa | B49: 77b5d09c077f4d6bb71031d0575f0baa | C49: 18e6b9953dd9f7d6e3b10e0671cb008eac9fc853368c8a634e8cde7256477223 | D49: 49 | F49: MOBILETRENDS | G49: RETURNED | J49: 0 | L49: 0 | M49: {"in":46,"DATE":"2/19/2026","IMEI":"","NAME":"MOBILETRENDS","TIME":1,"PRICE":"\u20a612,000.00","STATUS":"RETURNED","PAID DATE":"","RECORD_ID":"77b5d09c077f4d6bb71031d0575f0baa","Amount paid":"","DESCRIPTION":"IPHONE 11 APPLE ID INACTIVE FIX","PHONE NUMBER":"","DEAL LOCATION":"","INTERNAL NOTE":"","EXPENSE AMOUNT":"","CALCULATED PROFIT":"","EXPENSE DESCRIPTION":"","IMEI FOR SWAPPED DEAL":""} | N49: 2026-05-11T22:00:09.855781+01:00 | O49: 2026-05-11T22:00:09.855781+01:00
A50: cb1db8e857d84f30a5621e87a66cf2fd | B50: cb1db8e857d84f30a5621e87a66cf2fd | C50: 9c27d577bffdeac4de91495a0505ebaa9f6d79718064f79f4ee94fdf0f219c0c | D50: 50 | F50: BARRY | G50: UNPAID | J50: 0 | L50: 0 | M50: {"in":47,"DATE":"2/19/2026","IMEI":"","NAME":"BARRY","TIME":2,"PRICE":"\u20a62,500.00","STATUS":"UNPAID","PAID DATE":"","RECORD_ID":"cb1db8e857d84f30a5621e87a66cf2fd","Amount paid":"","DESCRIPTION":"PURPLE 14 PRO MAX IOS UPDATE TO 26.3","PHONE NUMBER":2347031524935,"DEAL LOCATION":"","INTERNAL NOTE":"","EXPENSE AMOUNT":"","CALCULATED PROFIT":"","EXPENSE DESCRIPTION":"","IMEI FOR SWAPPED DEAL":""} | N50: 2026-05-11T22:00:09.855781+01:00 | O50: 2026-05-11T22:00:09.855781+01:00
...

Sheet BACKUP_STOCK_PRODUCTS
A1: sync_key | B1: record_id | C1: source_hash | D1: sheet_row_num | E1: imei | F1: customer_name | G1: payment_status | H1: payment_date | I1: paid_date | J1: expense_amount | K1: expense_description | L1: calculated_profit | M1: payload_json | N1: created_at | O1: updated_at
A2: f4c0873e338746d89216ac34497d6f0b | B2: f4c0873e338746d89216ac34497d6f0b | C2: 14a8cfe388308096c071b929309db327aa00bc0bd9a7e0cb8be6c50c4e9dd2ab | D2: 4 | E2: 359428791784739 | F2: IYANUOLUWA DEMIGLOBAL | G2: SOLD | J2: 0 | L2: 0 | M2: {"S/N":"1","IMEI":"359428791784739","TIME":"","COLOUR":"BLUE TITANIUM","DEVICE":"IPHONE","STORAGE":"256GB","Column 17":"","Column 24":"","Column 25":"","Column 26":"","Column 27":"","Column 28":"","Column 29":"","Column 30":"","Column 31":"","Column 36":"","Column 37":"","Column 38":"","Column 39":"","Column 40":"","Column 41":"","Column 42":"","Column 43":"","Column 44":"","Column 45":"","Column 46":"","Column 47":"","PAID DATE":"","RECORD_ID":"f4c0873e338746d89216ac34497d6f0b","BATTERY. H":"89","CONDITIONS":"NONE","COST PRICE":"","DATE BOUGHT":"OCTOBER, 6, 2024","DESCRIPTION":"IPHONE 15 PRO MAX","DEAL LOCATION":"","INTERNAL NOTE":"","NAME OF BUYER":"IYANUOLUWA DEMIGLOBAL","EXPENSE AMOUNT":"","NAME OF SELLER":"O.Z GADGET","PRODUCT STATUS":"SOLD","STATUS OF DEVICE":"LOCKED","CALCULATED PROFIT":"","EXPENSE DESCRIPTION":"","PHONE NUMBER OF BUYER":"08088480573","AVAILABILITY/DATE SOLD":"","PHONE NUMBER OF SELLER":"08106293924","RECEIPT & EVIDIENCE LINK":""} | N2: 2026-05-11T22:24:59.340311+01:00 | O2: 2026-05-11T22:24:59.340311+01:00
A3: 3768e50b53064b5ba6ba5b400c6d2b89 | B3: 3768e50b53064b5ba6ba5b400c6d2b89 | C3: 2a7873bf50294f5b00dea2eb84e63f1f5018f8f5c69dd9bd1650e67c9bd88982 | D3: 5 | E3: 352846114777907 | F3: OLUFAD TELECOMMUNICATION | G3: SOLD | J3: 0 | L3: 0 | M3: {"S/N":"2","IMEI":"352846114777907","TIME":"","COLOUR":"GOLD","DEVICE":"IPHONE","STORAGE":"128GB","Column 17":"","Column 24":"","Column 25":"","Column 26":"","Column 27":"","Column 28":"","Column 29":"","Column 30":"","Column 31":"","Column 36":"","Column 37":"","Column 38":"","Column 39":"","Column 40":"","Column 41":"","Column 42":"","Column 43":"","Column 44":"","Column 45":"","Column 46":"","Column 47":"","PAID DATE":"","RECORD_ID":"3768e50b53064b5ba6ba5b400c6d2b89","BATTERY. H":"90","CONDITIONS":"NONE","COST PRICE":"","DATE BOUGHT":"SEPTEMBER, 30, 2024","DESCRIPTION":"IPHONE 13 PRO MAX","DEAL LOCATION":"","INTERNAL NOTE":"","NAME OF BUYER":"OLUFAD TELECOMMUNICATION","EXPENSE AMOUNT":"","NAME OF SELLER":"PAPPYTECH GADGET","PRODUCT STATUS":"SOLD","STATUS OF DEVICE":"LOCKED (THEN UNLOCKED)","CALCULATED PROFIT":"","EXPENSE DESCRIPTION":"","PHONE NUMBER OF BUYER":"09033780767","AVAILABILITY/DATE SOLD":"12/23/2024","PHONE NUMBER OF SELLER":"09064677372","RECEIPT & EVIDIENCE LINK":""} | N3: 2026-05-11T22:00:10.014056+01:00 | O3: 2026-05-11T22:00:10.014056+01:00
A4: cfa6b8aee46f496baf1bbf870b763913 | B4: cfa6b8aee46f496baf1bbf870b763913 | C4: 340828b1a19347fddcc37394bc5c1079fa907512081be760f04273f3ee20640c | D4: 6 | E4: RWRGQWTLDG | F4: RUL | G4: SOLD | J4: 0 | L4: 0 | M4: {"S/N":"3","IMEI":"RWRGQWTLDG","TIME":"","COLOUR":"BLACK","DEVICE":"IWATCH","STORAGE":"90+","Column 17":"","Column 24":"","Column 25":"","Column 26":"","Column 27":"","Column 28":"","Column 29":"","Column 30":"","Column 31":"","Column 36":"","Column 37":"","Column 38":"","Column 39":"","Column 40":"","Column 41":"","Column 42":"","Column 43":"","Column 44":"","Column 45":"","Column 46":"","Column 47":"","PAID DATE":"","RECORD_ID":"cfa6b8aee46f496baf1bbf870b763913","BATTERY. H":"97","CONDITIONS":"NONE","COST PRICE":"","DATE BOUGHT":"SEPTEMBER, 30, 2024","DESCRIPTION":"IWATCH SERIES 7","DEAL LOCATION":"","INTERNAL NOTE":"","NAME OF BUYER":"RUL ","EXPENSE AMOUNT":"","NAME OF SELLER":"AKINRULI","PRODUCT STATUS":"SOLD","STATUS OF DEVICE":"UNLOCKED (GPS)","CALCULATED PROFIT":"","EXPENSE DESCRIPTION":"","PHONE NUMBER OF BUYER":"08153978826","AVAILABILITY/DATE SOLD":"","PHONE NUMBER OF SELLER":"08153978826","RECEIPT & EVIDIENCE LINK":""} | N4: 2026-05-11T22:00:10.014056+01:00 | O4: 2026-05-11T22:00:10.014056+01:00
A5: de50ff235ae54e7bab6d84c727a8dfdb | B5: de50ff235ae54e7bab6d84c727a8dfdb | C5: 7cc6965aa60791361cff910a084530b1728b34d8017b28783e3c8291cf1cdfa3 | D5: 7 | E5: 351646277325994 | F5: MARVY FCG | G5: SOLD | J5: 0 | L5: 0 | M5: {"S/N":"4","IMEI":"351646277325994","TIME":"","COLOUR":"BLUE TITANIUM","DEVICE":"IPHONE","STORAGE":"256GB","Column 17":"","Column 24":"","Column 25":"","Column 26":"","Column 27":"","Column 28":"","Column 29":"","Column 30":"","Column 31":"","Column 36":"","Column 37":"","Column 38":"","Column 39":"","Column 40":"","Column 41":"","Column 42":"","Column 43":"","Column 44":"","Column 45":"","Column 46":"","Column 47":"","PAID DATE":"","RECORD_ID":"de50ff235ae54e7bab6d84c727a8dfdb","BATTERY. H":"100","CONDITIONS":"NONE","COST PRICE":"","DATE BOUGHT":"SEPTEMBER, 25, 2024","DESCRIPTION":"IPHONE 15 PRO MAX","DEAL LOCATION":"","INTERNAL NOTE":"","NAME OF BUYER":"MARVY FCG","EXPENSE AMOUNT":"","NAME OF SELLER":"O.Z GADGET","PRODUCT STATUS":"SOLD","STATUS OF DEVICE":"LOCKED","CALCULATED PROFIT":"","EXPENSE DESCRIPTION":"","PHONE NUMBER OF BUYER":"08138375326","AVAILABILITY/DATE SOLD":"October 26, 2024","PHONE NUMBER OF SELLER":"08106293924","RECEIPT & EVIDIENCE LINK":""} | N5: 2026-05-11T22:00:10.014056+01:00 | O5: 2026-05-11T22:00:10.014056+01:00
A6: 66863ec018eb4afcaa4f3d1c0dd63c8c | B6: 66863ec018eb4afcaa4f3d1c0dd63c8c | C6: 62d23667755195e63b5d5234f30938f95904ff364f3992fe99461567ff17b30e | D6: 8 | E6: 357343096709841 | F6: AZIMUTHAL | G6: SOLD | J6: 0 | L6: 0 | M6: {"S/N":"5","IMEI":"357343096709841","TIME":"","COLOUR":"BLUE","DEVICE":"IPHONE","STORAGE":"64GB","Column 17":"","Column 24":"","Column 25":"","Column 26":"","Column 27":"","Column 28":"","Column 29":"","Column 30":"","Column 31":"","Column 36":"","Column 37":"","Column 38":"","Column 39":"","Column 40":"","Column 41":"","Column 42":"","Column 43":"","Column 44":"","Column 45":"","Column 46":"","Column 47":"","PAID DATE":"","RECORD_ID":"66863ec018eb4afcaa4f3d1c0dd63c8c","BATTERY. H":"86","CONDITIONS":"NONE","COST PRICE":"","DATE BOUGHT":"OCTOBER, 9, 2024","DESCRIPTION":"IPHONE XR ","DEAL LOCATION":"","INTERNAL NOTE":"","NAME OF BUYER":"AZIMUTHAL","EXPENSE AMOUNT":"","NAME OF SELLER":"COWBELL","PRODUCT STATUS":"SOLD","STATUS OF DEVICE":"UNLOCKED","CALCULATED PROFIT":"","EXPENSE DESCRIPTION":"","PHONE NUMBER OF BUYER":"08135659717","AVAILABILITY/DATE SOLD":"OCTOBER, 9, 2024","PHONE NUMBER OF SELLER":"08027964718","RECEIPT & EVIDIENCE LINK":""} | N6: 2026-05-11T22:00:10.014056+01:00 | O6: 2026-05-11T22:00:10.014056+01:00
A7: a7c86fc0132e49188954358ad06be091 | B7: a7c86fc0132e49188954358ad06be091 | C7: 914a6f96c95e55f4d90856c90dcc818e71f98e5910ac6810cd4f5586f1f5e81e | D7: 9 | E7: 355591190747054 | F7: AYOMIDE FROM KING | G7: SOLD | J7: 0 | L7: 0 | M7: {"S/N":"6","IMEI":"355591190747054","TIME":"","COLOUR":"PACIFIC BLUE","DEVICE":"IPHONE","STORAGE":"128GB","Column 17":"","Column 24":"","Column 25":"","Column 26":"","Column 27":"","Column 28":"","Column 29":"","Column 30":"","Column 31":"","Column 36":"","Column 37":"","Column 38":"","Column 39":"","Column 40":"","Column 41":"","Column 42":"","Column 43":"","Column 44":"","Column 45":"","Column 46":"","Column 47":"","PAID DATE":"","RECORD_ID":"a7c86fc0132e49188954358ad06be091","BATTERY. H":"89","CONDITIONS":"NONE","COST PRICE":"","DATE BOUGHT":"SEPTEMBER, 5, 2024","DESCRIPTION":"IPHONE 12 PRO MAX","DEAL LOCATION":"","INTERNAL NOTE":"","NAME OF BUYER":"AYOMIDE FROM KING","EXPENSE AMOUNT":"","NAME OF SELLER":"HAYKINZ TECH","PRODUCT STATUS":"SOLD","STATUS OF DEVICE":"LOCKED","CALCULATED PROFIT":"","EXPENSE DESCRIPTION":"","PHONE NUMBER OF BUYER":"07036545521","AVAILABILITY/DATE SOLD":"OCTOBER, 25, 2024","PHONE NUMBER OF SELLER":"07030279101","RECEIPT & EVIDIENCE LINK":""} | N7: 2026-05-11T22:00:10.014056+01:00 | O7: 2026-05-11T22:00:10.014056+01:00
A8: 0b280c8acbac4c488c0d68ea13e375b9 | B8: 0b280c8acbac4c488c0d68ea13e375b9 | C8: d514a45e827bc32624e7f37fd801279408187400d9d64b3dbb8657d62a7f01ba | D8: 10 | E8: 358614725800789 | F8: CLARK TMOBILE | G8: SOLD | J8: 0 | L8: 0 | M8: {"S/N":"7","IMEI":"358614725800789","TIME":"","COLOUR":"YELLOW","DEVICE":"IPHONE","STORAGE":"128GB","Column 17":"","Column 24":"","Column 25":"","Column 26":"","Column 27":"","Column 28":"","Column 29":"","Column 30":"","Column 31":"","Column 36":"","Column 37":"","Column 38":"","Column 39":"","Column 40":"","Column 41":"","Column 42":"","Column 43":"","Column 44":"","Column 45":"","Column 46":"","Column 47":"","PAID DATE":"","RECORD_ID":"0b280c8acbac4c488c0d68ea13e375b9","BATTERY. H":"100","CONDITIONS":"NONE","COST PRICE":"","DATE BOUGHT":"OCTOBER, 9, 2024","DESCRIPTION":"IPHONE 15","DEAL LOCATION":"","INTERNAL NOTE":"","NAME OF BUYER":"CLARK TMOBILE","EXPENSE AMOUNT":"","NAME OF SELLER":"STAR BOX","PRODUCT STATUS":"SOLD","STATUS OF DEVICE":"LOCKED/INACTIVE (THEN UNLOCKED)","CALCULATED PROFIT":"","EXPENSE DESCRIPTION":"","PHONE NUMBER OF BUYER":"07064459910","AVAILABILITY/DATE SOLD":"OCTOBER, 9, 2024","PHONE NUMBER OF SELLER":"09063620334","RECEIPT & EVIDIENCE LINK":""} | N8: 2026-05-11T22:00:10.014056+01:00 | O8: 2026-05-11T22:00:10.014056+01:00
A9: 1fd8108519d94ba4ab573f6929f093e1 | B9: 1fd8108519d94ba4ab573f6929f093e1 | C9: 776c74d1412901845cd096bbc3fd3bd345fc84d89855d51676b4b61b17ed922d | D9: 11 | E9: 356028100922757 | F9: AZIMUTHAL | G9: SOLD | J9: 0 | L9: 0 | M9: {"S/N":"8","IMEI":"356028100922757","TIME":"","COLOUR":"BLUE","DEVICE":"SAMSUNG ","STORAGE":"8/128G","Column 17":"","Column 24":"","Column 25":"","Column 26":"","Column 27":"","Column 28":"","Column 29":"","Column 30":"","Column 31":"","Column 36":"","Column 37":"","Column 38":"","Column 39":"","Column 40":"","Column 41":"","Column 42":"","Column 43":"","Column 44":"","Column 45":"","Column 46":"","Column 47":"","PAID DATE":"","RECORD_ID":"1fd8108519d94ba4ab573f6929f093e1","BATTERY. H":"-","CONDITIONS":"NONE","COST PRICE":"","DATE BOUGHT":"OCTOBER, 5, 2024","DESCRIPTION":"SAMSUNG GALAXY S10","DEAL LOCATION":"","INTERNAL NOTE":"","NAME OF BUYER":"AZIMUTHAL","EXPENSE AMOUNT":"","NAME OF SELLER":"DENIS4WARD TECHNOLOGY ","PRODUCT STATUS":"SOLD","STATUS OF DEVICE":"UNLOCKED","CALCULATED PROFIT":"","EXPENSE DESCRIPTION":"","PHONE NUMBER OF BUYER":"08135659717","AVAILABILITY/DATE SOLD":"OCTOBER, 9, 2024","PHONE NUMBER OF SELLER":"08038551439","RECEIPT & EVIDIENCE LINK":""} | N9: 2026-05-11T22:00:10.014056+01:00 | O9: 2026-05-11T22:00:10.014056+01:00
A10: 4e9da763a2e2438a88fed668796c4ca4 | B10: 4e9da763a2e2438a88fed668796c4ca4 | C10: ab85df81f1e5166a4ddb7d6ff8c3f908a979e585842eb959c7e6ee5d4693c9ca | D10: 12 | E10: 356611841620473 | F10: STARBOX | G10: SOLD | J10: 0 | L10: 0 | M10: {"S/N":"9","IMEI":"356611841620473","TIME":"","COLOUR":"NATURAL TITANIUM","DEVICE":"IPHONE","STORAGE":"128GB","Column 17":"","Column 24":"","Column 25":"","Column 26":"","Column 27":"","Column 28":"","Column 29":"","Column 30":"","Column 31":"","Column 36":"","Column 37":"","Column 38":"","Column 39":"","Column 40":"","Column 41":"","Column 42":"","Column 43":"","Column 44":"","Column 45":"","Column 46":"","Column 47":"","PAID DATE":"","RECORD_ID":"4e9da763a2e2438a88fed668796c4ca4","BATTERY. H":"100","CONDITIONS":"NONE","COST PRICE":"","DATE BOUGHT":"OCTOBER, 11, 2024","DESCRIPTION":"IPHONE 15 PRO","DEAL LOCATION":"","INTERNAL NOTE":"","NAME OF BUYER":"STARBOX","EXPENSE AMOUNT":"","NAME OF SELLER":"DENIS IPHONE CART","PRODUCT STATUS":"SOLD","STATUS OF DEVICE":"LOCKED","CALCULATED PROFIT":"","EXPENSE DESCRIPTION":"","PHONE NUMBER OF BUYER":"09063620334","AVAILABILITY/DATE SOLD":"OCTOBER, 29, 2024","PHONE NUMBER OF SELLER":"07019540544","RECEIPT & EVIDIENCE LINK":""} | N10: 2026-05-11T22:00:10.014056+01:00 | O10: 2026-05-11T22:00:10.014056+01:00
A11: 3da6080066fd4c92b3d68a4eb2d3352e | B11: 3da6080066fd4c92b3d68a4eb2d3352e | C11: 0d7902f183f31b329c93ba8901cc54f3ae20ecc58a158b541d0d9d8010168fff | D11: 13 | E11: C02CQ657ML7H | G11: SOLD | J11: 0 | L11: 0 | M11: {"S/N":"10","IMEI":"C02CQ657ML7H","TIME":"","COLOUR":"SILVER","DEVICE":"MACBOOK","STORAGE":"16/512GB","Column 17":"","Column 24":"","Column 25":"","Column 26":"","Column 27":"","Column 28":"","Column 29":"","Column 30":"","Column 31":"","Column 36":"","Column 37":"","Column 38":"","Column 39":"","Column 40":"","Column 41":"","Column 42":"","Column 43":"","Column 44":"","Column 45":"","Column 46":"","Column 47":"","PAID DATE":"","RECORD_ID":"3da6080066fd4c92b3d68a4eb2d3352e","BATTERY. H":"192 cc","CONDITIONS":"NONE","COST PRICE":"","DATE BOUGHT":"OCTOBER, 11, 2024","DESCRIPTION":"MACBOOK PRO 2020","DEAL LOCATION":"","INTERNAL NOTE":"","NAME OF BUYER":"","EXPENSE AMOUNT":"","NAME OF SELLER":"GADGET AND EXCHANGE","PRODUCT STATUS":"SOLD","STATUS OF DEVICE":"UNLOCKED (NO FMI)","CALCULATED PROFIT":"","EXPENSE DESCRIPTION":"","PHONE NUMBER OF BUYER":"","AVAILABILITY/DATE SOLD":"","PHONE NUMBER OF SELLER":"08142246838","RECEIPT & EVIDIENCE LINK":""} | N11: 2026-05-11T22:00:10.014056+01:00 | O11: 2026-05-11T22:00:10.014056+01:00
A12: 7b37f8c77cba4eeeb6a371dc23875e9b | B12: 7b37f8c77cba4eeeb6a371dc23875e9b | C12: 4d3fd4677d4701cf5f6e764b52627b3caf855eff4900ce886c2ca8b3ba2f0982 | D12: 14 | E12: 358835961632491/17 | F12: GEORGE | G12: SOLD | J12: 0 | L12: 0 | M12: {"S/N":"11","IMEI":"358835961632491/17","TIME":"","COLOUR":"BLACK","DEVICE":"SAMSUNG ","STORAGE":"12/512GB","Column 17":"","Column 24":"","Column 25":"","Column 26":"","Column 27":"","Column 28":"","Column 29":"","Column 30":"","Column 31":"","Column 36":"","Column 37":"","Column 38":"","Column 39":"","Column 40":"","Column 41":"","Column 42":"","Column 43":"","Column 44":"","Column 45":"","Column 46":"","Column 47":"","PAID DATE":"","RECORD_ID":"7b37f8c77cba4eeeb6a371dc23875e9b","BATTERY. H":"100","CONDITIONS":"NONE","COST PRICE":"","DATE BOUGHT":"AUGUST, 5, 2024","DESCRIPTION":"SAMSUNG GALAXY S23 ULTRA","DEAL LOCATION":"","INTERNAL NOTE":"","NAME OF BUYER":"GEORGE","EXPENSE AMOUNT":"","NAME OF SELLER":"DAMBOX GADGETS","PRODUCT STATUS":"SOLD","STATUS OF DEVICE":"UNLOCKED","CALCULATED PROFIT":"","EXPENSE DESCRIPTION":"","PHONE NUMBER OF BUYER":"08168364881","AVAILABILITY/DATE SOLD":"12/7/2024","PHONE NUMBER OF SELLER":"09040943517","RECEIPT & EVIDIENCE LINK":""} | N12: 2026-05-11T22:00:10.014056+01:00 | O12: 2026-05-11T22:00:10.014056+01:00
A13: d9b909f7d5084ca7a454f266ee9ce09b | B13: d9b909f7d5084ca7a454f266ee9ce09b | C13: 695e7926165babe9e52ddbb29a13846a34fbc68d92f96948ad996aed324a8b89 | D13: 15 | E13: 356370160169592 | F13: NURUDEEN | G13: SOLD | J13: 0 | L13: 0 | M13: {"S/N":"12","IMEI":"356370160169592","TIME":"","COLOUR":"SIERRA BLUE","DEVICE":"IPHONE","STORAGE":"128GB","Column 17":"","Column 24":"","Column 25":"","Column 26":"","Column 27":"","Column 28":"","Column 29":"","Column 30":"","Column 31":"","Column 36":"","Column 37":"","Column 38":"","Column 39":"","Column 40":"","Column 41":"","Column 42":"","Column 43":"","Column 44":"","Column 45":"","Column 46":"","Column 47":"","PAID DATE":"","RECORD_ID":"d9b909f7d5084ca7a454f266ee9ce09b","BATTERY. H":"93","CONDITIONS":"NONE","COST PRICE":"","DATE BOUGHT":"AUGUST, 31, 2024","DESCRIPTION":"IPHONE 13 PRO MAX","DEAL LOCATION":"","INTERNAL NOTE":"","NAME OF BUYER":"NURUDEEN","EXPENSE AMOUNT":"","NAME OF SELLER":"NURUDEEN","PRODUCT STATUS":"SOLD","STATUS OF DEVICE":"LOCKED","CALCULATED PROFIT":"","EXPENSE DESCRIPTION":"","PHONE NUMBER OF BUYER":"07067426927","AVAILABILITY/DATE SOLD":"OCTOBER, 12, 2024","PHONE NUMBER OF SELLER":"07067426927","RECEIPT & EVIDIENCE LINK":""} | N13: 2026-05-11T22:00:10.014056+01:00 | O13: 2026-05-11T22:00:10.014056+01:00
